<?xml version="1.0"?>
<robot xmlns:xacro="http://www.ros.org/wiki/xacro">
  <!-- link wheel -->
  <xacro:macro name="link_wheel" params="name">
    <link name="${name}">
      <inertial>
        <mass value="0.045"/>
        <origin rpy="0 1.5707 1.5707" xyz="0 0 0"/>
        <inertia ixx="0.00052666666" ixy="0" ixz="0" iyy="0.00052666666" iyz="0" izz="0.001"/>
      </inertial>
      
      <collision name="${name}_collision">
        <origin rpy="0 1.5707 1.5707" xyz="0 0 0" />
        <geometry>
          <cylinder length="0.017" radius="0.021"/>
        </geometry>
      </collision>
      
      <visual name="${name}_visual">
        <origin rpy="0 1.5707 1.5707" xyz="0 0 0"/>
        <geometry>
            <cylinder length="0.017" radius="0.021"/>
        </geometry>      
        <material name="black"/>
      </visual>
    </link>
  </xacro:macro>
  <!-- end of link Wheel -->

  <!-- joint wheel -->
  <xacro:macro name="joint_wheel" params="name child origin_xyz">
    <joint name="${name}" type="continuous">
      <origin rpy="0 0 0" xyz="${origin_xyz}"/>
      <child link="${name}"/>
      <parent link="link_chassis"/>
      <axis rpy="0 0 0" xyz="0 1 0"/>
      <limit effort="10000" velocity="1000"/>
      <joint_properties damping="1.0" friction="1.0" />
    </joint>
  </xacro:macro>
  <!-- end of joint wheel -->
</robot>